Workbook

Sheet Calculadora
A1: CALCULADORA SOLAR V4 - CON LISTAS DESPLEGABLES Y CÁLCULO DE STRINGS
A2: Use las FLECHAS 🔽 en celdas amarillas para seleccionar opciones
A4: N° | B4: EQUIPO/APARATO | C4: CANT. | D4: POT.(W) | E4: H/DÍA | F4: CONSUMO(Wh) | G4: FACTOR | H4: CONSUMO REAL(Wh)
A5: 1 | B5: Cocina eléctrica | C5: 1 | D5: 2000 | E5: 1.5 | F5: =C5*D5*E5 | G5: 0.7 | H5: =F5*G5
A6: 2 | B6: Olla multipropósito | C6: 1 | D6: 1000 | E6: 1 | F6: =C6*D6*E6 | G6: 0.8 | H6: =F6*G6
A7: 3 | B7: Cocina de inducción | C7: 1 | D7: 1800 | E7: 1 | F7: =C7*D7*E7 | G7: 0.7 | H7: =F7*G7
A8: 4 | B8: Refrigerador | C8: 1 | D8: 150 | E8: 24 | F8: =C8*D8*E8 | G8: 0.4 | H8: =F8*G8
A9: 5 | B9: Nevera | C9: 1 | D9: 120 | E9: 24 | F9: =C9*D9*E9 | G9: 0.4 | H9: =F9*G9
A10: 6 | B10: Horno de aire | C10: 1 | D10: 1500 | E10: 0.5 | F10: =C10*D10*E10 | G10: 0.8 | H10: =F10*G10
A11: 7 | B11: Batidora | C11: 1 | D11: 300 | E11: 0.3 | F11: =C11*D11*E11 | G11: 1 | H11: =F11*G11
A12: 8 | B12: Microondas | C12: 1 | D12: 1200 | E12: 0.5 | F12: =C12*D12*E12 | G12: 0.8 | H12: =F12*G12
A13: 9 | B13: Lavadora | C13: 1 | D13: 400 | E13: 1 | F13: =C13*D13*E13 | G13: 0.8 | H13: =F13*G13
A14: 10 | B14: Ducha eléctrica | C14: 1 | D14: 4500 | E14: 0.5 | F14: =C14*D14*E14 | G14: 1 | H14: =F14*G14
A15: 11 | B15: TV 55" | C15: 1 | D15: 120 | E15: 6 | F15: =C15*D15*E15 | G15: 1 | H15: =F15*G15
A16: 12 | B16: Ventiladores | C16: 4 | D16: 60 | E16: 8 | F16: =C16*D16*E16 | G16: 1 | H16: =F16*G16
... A22: 18 | B22: Teatro casa | C22: 1 | D22: 150 | E22: 3 | F22: =C22*D22*E22 | G22: 1 | H22: =F22*G22
A23: TOTAL CONSUMO DIARIO | F23: =SUM(F5:F22) | H23: =SUM(H5:H22)
A25: ⚙️ CONFIGURACIÓN DEL SISTEMA (Use flechas 🔽 para seleccionar)
B26: PARÁMETRO | D26: VALOR | E26: UNIDAD | F26: DESCRIPCIÓN
B27: Voltaje del sistema | D27: 48 | E27: V | F27: Seleccione: 12V/24V/48V/96V
B28: Frecuencia | D28: 60 | E28: Hz | F28: Seleccione: 50Hz o 60Hz
B29: Tipo de red | D29: 110V Monofásico | F29: Use lista desplegable
B30: Tipo de inversor | D30: Híbrido | F30: Use lista desplegable
A31: ☀️ ESPECIFICACIONES DEL PANEL SOLAR
B32: PARÁMETRO | D32: VALOR | E32: UNIDAD | F32: DESCRIPCIÓN
B33: Potencia nominal (Pmax) | D33: 400 | E33: W | F33: Potencia del panel
B34: Voltaje en Pmax (Vmp) | D34: 36.5 | E34: V | F34: Voltaje a máxima potencia
B35: Corriente en Pmax (Imp) | D35: 10.96 | E35: A | F35: Corriente a máxima potencia
B36: Configuración string | D36: Serie | F36: Serie o Paralelo
B37: Paneles por string | D37: 1 | E37: unidades | F37: Cantidad de paneles por string
A38: 🔌 CÁLCULOS DEL STRING DE PANELES
B39: PARÁMETRO | D39: RESULTADO | E39: UNIDAD | F39: FÓRMULA
B40: Voltaje del string (Vstring) | D40: 73 | E40: V | F40: EDITAR según modelo inversor
B41: Corriente del string (Istring) | D41: 10.96 | E41: A | F41: EDITAR según modelo inversor
B42: Potencia del string | D42: 800 | E42: W | F42: EDITAR según configuración
A43: 🔋 PARÁMETROS DE BATERÍAS Y GENERACIÓN
B44: PARÁMETRO | D44: VALOR | E44: UNIDAD | F44: DESCRIPCIÓN
B45: Días de autonomía | D45: 1 | E45: días | F45: Reserva del banco
B46: Tipo de batería | D46: Litio | F46: Use lista desplegable
B47: Profundidad descarga | D47: 0.8 | F47: Según tipo batería
...

Sheet Lista de Materiales
A1: LISTA DE MATERIALES - SISTEMA FOTOVOLTAICO
A2: Listado completo de componentes, cantidades y especificaciones técnicas
A4: ÍTEM | B4: CATEGORÍA | C4: COMPONENTE | D4: CANTIDAD | E4: ESPECIFICACIÓN | F4: UNIDAD | G4: PRECIO UNIT. | H4: SUBTOTAL
A5: 1 | B5: PANELES SOLARES | C5: Paneles Fotovoltaicos | D5: =Calculadora!D64 | E5: =Calculadora!D34&"W - Vmp: "&Calculadora!D35&"V - Imp: "&Calculadora!D36&"A" | F5: unidades | G5: 175 | H5: =D5*G5
A6: 2 | B6: PANELES SOLARES | C6: Estructura de montaje | D6: =Calculadora!D64 | E6: Aluminio con tornillería inoxidable | F6: kit | G6: 15 | H6: =D6*G6
A7: 3 | B7: PANELES SOLARES | C7: Rieles de montaje | D7: =ROUNDUP(Calculadora!D64/4,0)*2 | E7: Riel aluminio 4.2m | F7: unidades | G7: 25 | H7: =D7*G7
A8: 4 | B8: PANELES SOLARES | C8: Kit de tornillería | D8: 1 | E8: Tornillos, tuercas, arandelas inox | F8: kit | G8: 50 | H8: =D8*G8
A9: 5 | B9: INVERSOR | C9: Inversor híbrido | D9: 1 | E9: =ROUND(Calculadora!D66/1000,1)&"kW @ "&Calculadora!D27&"V - "&Calculadora!D29 | F9: unidad | G9: 1500 | H9: =D9*G9
A10: 6 | B10: INVERSOR | C10: Controlador de carga MPPT | D10: 1 | E10: =ROUND(Calculadora!D67,0)&"A para "&Calculadora!D27&"V" | F10: unidad | G10: 400 | H10: =D10*G10
A11: 7 | B11: BATERÍAS | C11: Banco de baterías | D11: =ROUNDUP(Calculadora!D61/200,0) | E11: =Calculadora!D48&" - 200Ah - "&Calculadora!D27&"V" | F11: unidades | G11: 550 | H11: =D11*G11
A12: 8 | B12: BATERÍAS | C12: Cables de interconexión baterías | D12: =ROUNDUP(Calculadora!D61/200,0)+1 | E12: Cable 2/0 AWG, 1m c/u | F12: unidades | G12: 15 | H12: =D12*G12
A13: 9 | B13: BATERÍAS | C13: Terminales y conectores | D13: 1 | E13: Kit completo para baterías | F13: kit | G13: 40 | H13: =D13*G13
A14: 10 | B14: CABLEADO DC | C14: Cable solar DC 10AWG | D14: 1 | E14: 50 metros | F14: rollo | G14: 250 | H14: =D14*G14
A15: 11 | B15: CABLEADO DC | C15: Conectores MC4 | D15: =Calculadora!D64*2 | E15: Macho y hembra | F15: pares | G15: 3 | H15: =D15*G15
A16: 12 | B16: CABLEADO DC | C16: Cable 8AWG baterías-inversor | D16: 1 | E16: 10 metros | F16: rollo | G16: 80 | H16: =D16*G16
A17: 13 | B17: CABLEADO DC | C17: Fusibles DC | D17: =Calculadora!D65 | E17: =ROUND(Calculadora!D42*1.25,0)&"A por string" | F17: unidades | G17: 8 | H17: =D17*G17
A18: 14 | B18: CABLEADO AC | C18: Cable THW 10AWG | D18: 1 | E18: 30 metros entrada/salida | F18: rollo | G18: 150 | H18: =D18*G18
A19: 15 | B19: CABLEADO AC | C19: Cable tierra 8AWG | D19: 1 | E19: 40 metros | F19: rollo | G19: 80 | H19: =D19*G19
A20: 16 | B20: CABLEADO AC | C20: Ductos y canaletas | D20: 1 | E20: 20 metros | F20: lote | G20: 100 | H20: =D20*G20
A21: 17 | B21: PROTECCIONES | C21: Breakers DC | D21: =Calculadora!D65 | E21: Para protección strings | F21: unidades | G21: 25 | H21: =D21*G21
A22: 18 | B22: PROTECCIONES | C22: Breaker principal DC | D22: 1 | E22: =ROUND(Calculadora!D67,0)&"A bipolar" | F22: unidad | G22: 45 | H22: =D22*G22
A23: 19 | B23: PROTECCIONES | C23: Breaker AC entrada | D23: 1 | E23: Según red eléctrica | F23: unidad | G23: 30 | H23: =D23*G23
A24: 20 | B24: PROTECCIONES | C24: Breaker AC salida | D24: 1 | E24: Protección cargas | F24: unidad | G24: 30 | H24: =D24*G24
A25: 21 | B25: PROTECCIONES | C25: Supresor de picos (SPD) | D25: 2 | E25: DC y AC | F25: unidades | G25: 80 | H25: =D25*G25
A26: 22 | B26: TABLEROS | C26: Tablero de distribución DC | D26: 1 | E26: Con espacio para breakers | F26: unidad | G26: 120 | H26: =D26*G26
A27: 23 | B27: TABLEROS | C27: Tablero de distribución AC | D27: 1 | E27: Con espacio para breakers | F27: unidad | G27: 100 | H27: =D27*G27
A28: 24 | B28: TABLEROS | C28: Gabinete para inversor | D28: 1 | E28: Metálico con ventilación | F28: unidad | G28: 150 | H28: =D28*G28
A29: 25 | B29: PUESTA A TIERRA | C29: Varilla cooperweld | D29: 2 | E29: 1.8m x 5/8" | F29: unidades | G29: 25 | H29: =D29*G29
A30: 26 | B30: PUESTA A TIERRA | C30: Conector varilla-cable | D30: 2 | E30: Bronce | F30: unidades | G30: 8 | H30: =D30*G30
A31: 27 | B31: PUESTA A TIERRA | C31: Cemento conductivo | D31: 2 | E31: Bolsa 25kg | F31: bolsas | G31: 20 | H31: =D31*G31
A32: 28 | B32: MATERIALES VARIOS | C32: Etiquetas identificación | D32: 1 | E32: Para cables y equipos | F32: kit | G32: 15 | H32: =D32*G32
A33: 29 | B33: MATERIALES VARIOS | C33: Silicón sellante | D33: 2 | E33: Para impermeabilización | F33: tubos | G33: 12 | H33: =D33*G33
A34: 30 | B34: MATERIALES VARIOS | C34: Cinta aislante | D34: 4 | E34: Alta temperatura | F34: rollos | G34: 5 | H34: =D34*G34
... A36: 32 | B36: MATERIALES VARIOS | C36: Abrazaderas metálicas | D36: 1 | E36: Varias medidas | F36: kit | G36: 25 | H36: =D36*G36
A38: SUBTOTAL PANELES SOLARES | H38: =SUM(H5:H8)
A39: SUBTOTAL INVERSOR | H39: =SUM(H9:H10)
A40: SUBTOTAL BATERÍAS | H40: =SUM(H11:H13)
A41: SUBTOTAL CABLEADO DC | H41: =SUM(H14:H17)
A42: SUBTOTAL CABLEADO AC | H42: =SUM(H18:H20)
A43: SUBTOTAL PROTECCIONES | H43: =SUM(H21:H25)
...

Sheet Informe Cliente
A1: INFORME TÉCNICO
A2: SISTEMA FOTOVOLTAICO DE AUTOCONSUMO
A4: DATOS DEL CLIENTE
A5: Nombre: | B5: Cliente
A6: Email: | B6: apolivera1973@gmail.com
A7: Teléfono:
A8: Dirección:
A9: Fecha: | B9: =TODAY()
A10: CONFIGURACIÓN DEL SISTEMA
A11: Voltaje del sistema: | B11: =Calculadora!D27&" V"
A12: Frecuencia: | B12: =Calculadora!D28&" Hz"
A13: Tipo de red eléctrica: | B13: =Calculadora!D29
A14: Tipo de inversor: | B14: =Calculadora!D30
A16: RESULTADOS DEL DIMENSIONAMIENTO
A17: Consumo diario: | B17: =Calculadora!D53&" Wh/día"
A18: Potencia de paneles solares: | B18: =TEXT(Calculadora!D58,"0.00")&" Wp"
A19: Cantidad de paneles: | B19: =Calculadora!D61&" paneles de "&TEXT(Calculadora!D33,"0.00")&"W"
A20: Configuración de paneles: | B20: =Calculadora!D36&" - "&Calculadora!D37&" paneles/string"
A21: Voltaje del string: | B21: =TEXT(Calculadora!D40,"0.00")&" V"
A22: Corriente del string: | B22: =TEXT(Calculadora!D41,"0.00")&" A"
A23: Número de strings: | B23: =Calculadora!D60&" strings"
A24: Potencia del inversor: | B24: =ROUND(Calculadora!D62/1000,1)&" kW"
A25: Capacidad de baterías: | B25: =ROUND(Calculadora!D56,0)&" Ah @ "&Calculadora!D27&"V"
A26: Tipo de batería: | B26: =Calculadora!D46
A27: Corriente controlador: | B27: =ROUND(Calculadora!D63,0)&" A"
A29: OBSERVACIONES Y RECOMENDACIONES
A30: • Sistema dimensionado para consumo diario con 1 día de autonomía
A31: • Los paneles deben orientarse al sur (hemisferio norte) con inclinación óptima
A32: • Se recomienda instalación profesional certificada
A33: • Mantenimiento periódico de paneles y baterías requerido
A34: • Verificar normativa eléctrica local antes de instalación
