Workbook

Sheet Calculadora
A1: CALCULADORA SOLAR V4 - CON LISTAS DESPLEGABLES Y CÁLCULO DE STRINGS
A2: Use las FLECHAS 🔽 en celdas amarillas para seleccionar opciones
A4: N° | B4: EQUIPO/APARATO | C4: CANT. | D4: POT.(W) | E4: H/DÍA | F4: CONSUMO(Wh) | G4: FACTOR | H4: CONSUMO REAL(Wh) | I4: NOTAS
A5: 1 | B5: Cocina eléctrica | C5: 1 | D5: 2000 | E5: 1.5 | F5: =C5*D5*E5 | G5: 0.7 | H5: =F5*G5 | I5: Alto consumo
A6: 2 | B6: Olla multipropósito | C6: 1 | D6: 1000 | E6: 1 | F6: =C6*D6*E6 | G6: 0.8 | H6: =F6*G6 | I6: Moderado
A7: 3 | B7: Cocina de inducción | C7: 1 | D7: 1800 | E7: 1 | F7: =C7*D7*E7 | G7: 0.7 | H7: =F7*G7 | I7: Alto consumo
A8: 4 | B8: Refrigerador | C8: 1 | D8: 150 | E8: 24 | F8: =C8*D8*E8 | G8: 0.4 | H8: =F8*G8 | I8: Ciclo 40%
A9: 5 | B9: Nevera | C9: 1 | D9: 120 | E9: 24 | F9: =C9*D9*E9 | G9: 0.4 | H9: =F9*G9 | I9: Ciclo 40%
A10: 6 | B10: Horno de aire | C10: 1 | D10: 1500 | E10: 0.5 | F10: =C10*D10*E10 | G10: 0.8 | H10: =F10*G10 | I10: Ocasional
A11: 7 | B11: Batidora | C11: 1 | D11: 300 | E11: 0.3 | F11: =C11*D11*E11 | G11: 1 | H11: =F11*G11 | I11: Breve
A12: 8 | B12: Microondas | C12: 1 | D12: 1200 | E12: 0.5 | F12: =C12*D12*E12 | G12: 0.8 | H12: =F12*G12 | I12: Breve
A13: 9 | B13: Lavadora | C13: 1 | D13: 400 | E13: 1 | F13: =C13*D13*E13 | G13: 0.8 | H13: =F13*G13 | I13: Diario
A14: 10 | B14: Ducha eléctrica | C14: 1 | D14: 4500 | E14: 0.5 | F14: =C14*D14*E14 | G14: 1 | H14: =F14*G14 | I14: ALTO
A15: 11 | B15: TV 55" | C15: 1 | D15: 120 | E15: 6 | F15: =C15*D15*E15 | G15: 1 | H15: =F15*G15 | I15: Normal
A16: 12 | B16: Ventiladores | C16: 4 | D16: 60 | E16: 8 | F16: =C16*D16*E16 | G16: 1 | H16: =F16*G16 | I16: 4 unidades
... A22: 18 | B22: Teatro casa | C22: 1 | D22: 150 | E22: 3 | F22: =C22*D22*E22 | G22: 1 | H22: =F22*G22 | I22: Normal
A23: TOTAL CONSUMO DIARIO | F23: =SUM(F5:F22) | H23: =SUM(H5:H22)
A25: ⚙️ CONFIGURACIÓN DEL SISTEMA (Use flechas 🔽 para seleccionar)
B26: PARÁMETRO | D26: VALOR | E26: UNIDAD | F26: DESCRIPCIÓN
B27: Voltaje del sistema | D27: 48 | E27: V | F27: Seleccione: 12V/24V/48V/96V
B28: Frecuencia | D28: 60 | E28: Hz | F28: Seleccione: 50Hz o 60Hz
B29: Tipo de red | D29: 110V Monofásico | F29: Use lista desplegable
B30: Tipo de inversor | D30: Híbrido | F30: Use lista desplegable
A31: ☀️ ESPECIFICACIONES DEL PANEL SOLAR
B32: PARÁMETRO | D32: VALOR | E32: UNIDAD | F32: DESCRIPCIÓN
B33: Potencia nominal (Pmax) | D33: 400 | E33: W | F33: Potencia del panel
B34: Voltaje en Pmax (Vmp) | D34: 36.5 | E34: V | F34: Voltaje a máxima potencia
B35: Corriente en Pmax (Imp) | D35: 10.96 | E35: A | F35: Corriente a máxima potencia
B36: Configuración string | D36: Serie | F36: Serie o Paralelo
B37: Paneles por string | D37: 1 | E37: unidades | F37: Cantidad de paneles por string
A38: 🔌 CÁLCULOS DEL STRING DE PANELES
B39: PARÁMETRO | D39: RESULTADO | E39: UNIDAD | F39: FÓRMULA
B40: Voltaje del string (Vstring) | D40: =IF(D36="Serie",D34*D37,IF(D36="Paralelo",D34,D34*SQRT(D37))) | E40: V | F40: Vmp × Paneles (serie) o Vmp (paralelo)
B41: Corriente del string (Istring) | D41: =IF(D36="Serie",D35,IF(D36="Paralelo",D35*D37,D35*SQRT(D37))) | E41: A | F41: Imp (serie) o Imp × Paneles (paralelo)
B42: Potencia del string | D42: =D40*D41 | E42: W | F42: Vstring × Istring
A43: 🔋 PARÁMETROS DE BATERÍAS Y GENERACIÓN
B44: PARÁMETRO | D44: VALOR | E44: UNIDAD | F44: DESCRIPCIÓN
B45: Días de autonomía | D45: 1 | E45: días | F45: Reserva del banco
B46: Tipo de batería | D46: Litio | F46: Use lista desplegable
B47: Profundidad descarga | D47: 0.8 | F47: Según tipo batería
...

Sheet Informe Cliente
A1: INFORME TÉCNICO
A2: SISTEMA FOTOVOLTAICO DE AUTOCONSUMO
A4: DATOS DEL CLIENTE
A5: Nombre: | B5: Cliente
A6: Email: | B6: apolivera1973@gmail.com
A7: Teléfono:
A8: Dirección:
A9: Fecha: | B9: =TODAY()
A10: CONFIGURACIÓN DEL SISTEMA
A11: Voltaje del sistema: | B11: =Calculadora!D27&" V"
A12: Frecuencia: | B12: =Calculadora!D28&" Hz"
A13: Tipo de red eléctrica: | B13: =Calculadora!D29
A14: Tipo de inversor: | B14: =Calculadora!D30
A16: RESULTADOS DEL DIMENSIONAMIENTO
A17: Consumo diario: | B17: =Calculadora!D53&" Wh/día"
A18: Potencia de paneles solares: | B18: =Calculadora!D58&" Wp"
A19: Cantidad de paneles: | B19: =Calculadora!D59&" paneles de "&Calculadora!D33&"W"
A20: Configuración de paneles: | B20: =Calculadora!D36&" - "&Calculadora!D37&" paneles/string"
A21: Voltaje del string: | B21: =TEXT(Calculadora!D40,"0.00")&" V"
A22: Corriente del string: | B22: =TEXT(Calculadora!D41,"0.00")&" A"
A23: Número de strings: | B23: =Calculadora!D60&" strings"
A24: Potencia del inversor: | B24: =ROUND(Calculadora!D61/1000,1)&" kW"
A25: Capacidad de baterías: | B25: =ROUND(Calculadora!D56,0)&" Ah @ "&Calculadora!D27&"V"
A26: Tipo de batería: | B26: =Calculadora!D46
A27: Corriente controlador: | B27: =ROUND(Calculadora!D62,0)&" A"
A29: OBSERVACIONES Y RECOMENDACIONES
A30: • Sistema dimensionado para consumo diario con 1 día de autonomía
A31: • Los paneles deben orientarse al sur (hemisferio norte) con inclinación óptima
A32: • Se recomienda instalación profesional certificada
A33: • Mantenimiento periódico de paneles y baterías requerido
A34: • Verificar normativa eléctrica local antes de instalación
